File: 01_XRD/xrd-sul_bb_streda10.ras
*RAS_DATA_START
*RAS_HEADER_START
*DISP_FMT_X "%.2f"
*DISP_FMT_Y "%.0f"
*DISP_FULLSCALE "98032.0201920000"
*DISP_LINE_COLOR "255.0000000000"
*DISP_LINE_STYLE "0.0000000000"
*DISP_LINE_WIDTH "0.2500000000"
*DISP_NOTE "Collected Data-1"
*DISP_OFFSET_Y "0.0000000000"
*DISP_PEAKSEARCH_UNIT_Y "cps"
*DISP_RANGE_BOTTOM "0.0000000000"
*DISP_RANGE_LEFT "20.0000000000"
*DISP_RANGE_LOGCUTOFF "0.0100000000"
*DISP_RANGE_RIGHT "100.0000000000"
*DISP_RANGE_TOP "98032.0201920000"
*DISP_SCALE_MODE_Y "0.0000000000"
*DISP_TAB_NAME "2-Theta/Omega"
*DISP_TITLE_Y "Intensity"
*DISP_UNIT_Y "cps"
*DISP_WINDOW_NAME "MSG_MACROENGINE"
*FILE_COMMENT " "
*FILE_MD5 ""
*FILE_MEMO " "
*FILE_OPERATOR "rigaku"
*FILE_PART_ID "MEAS_KHP2_00068"
*FILE_SAMPLE " "
*FILE_TYPE "RAS_RAW"
*FILE_USERGROUP "System Manager"
*FILE_VERSION "1.0000000000"
*HW_ATTACHMENT_ID "ATT0025"
*HW_ATTACHMENT_NAME "標準|Standard"
*HW_COUNTER_ID-0 "CUT0041"
*HW_COUNTER_ID-1 "CUT0051"
*HW_COUNTER_ID-2 "CUT0020"
*HW_COUNTER_ID-3 "CSL0021"
*HW_COUNTER_ID-4 "CMC0021"
*HW_COUNTER_NAME-0 "D/teX Ultra 250|D/teX Ultra 250"
*HW_COUNTER_NAME-1 "HyPix 3000(H)|HyPix 3000(H)"
*HW_COUNTER_NAME-2 "None|None"
*HW_COUNTER_NAME-3 "BBM|BBM"
*HW_COUNTER_NAME-4 "検出器モノクロメータ|Detector monochromator"
*HW_COUNTER_SELECT_NAME "D/teX Ultra 250|D/teX Ultra 250"
*HW_GONIOMETER_ID "GON0024"
*HW_GONIOMETER_NAME "SmartLab(In-plane)|SmartLab(In-plane)"
*HW_GONIOMETER_RADIUS-0 "90.0"
*HW_GONIOMETER_RADIUS-1 "114.0"
*HW_GONIOMETER_RADIUS-2 "190.0"
*HW_GONIOMETER_RADIUS-3 "300.0"
*HW_GONIOMETER_RADIUS-4 "187.0"
*HW_GONIOMETER_RADIUS-5 "300.0"
*HW_GONIOMETER_RADIUS-6 "113.0"
*HW_GONIOMETER_RADIUS-7 "331.0"
*HW_I_OPT_ID-0 "CBO0021"
*HW_I_OPT_ID-1 "ICR0023"
*HW_I_OPT_ID-2 "ISL0021"
*HW_I_OPT_ID-3 "ISO0021"
*HW_I_OPT_ID-4 "IAD0021"
*HW_I_OPT_ID-5 "IPR0001"
*HW_I_OPT_NAME-0 "CBOユニット|CBO unit"
*HW_I_OPT_NAME-1 "標準入射光学ユニット|Standard incident optical unit"
*HW_I_OPT_NAME-2 "標準入射スリットボックス|Standard incident slit box"
*HW_I_OPT_NAME-3 "入射平行スリット|Incident parallel slit"
*HW_I_OPT_NAME-4 "長手制限スリット|Length limiting slit"
*HW_I_OPT_NAME-5 "None|None"
*HW_R_ATTENUATER_AUTOMODE "0"
*HW_R_OPT_ID-0 "RSS0021"
*HW_R_OPT_ID-1 "RCR0023"
*HW_R_OPT_ID-2 "RSO0021"
*HW_R_OPT_ID-3 "RRS0021"
*HW_R_OPT_ID-4 "ATN0021"
*HW_R_OPT_ID-5 "RFL0021"
*HW_R_OPT_ID-6 "RAD0021"
*HW_R_OPT_NAME-0 "標準受光スリットボックス1|Standard receiving slit box # 1"
*HW_R_OPT_NAME-1 "標準受光光学ユニット1|Standard receiving unit # 1"
*HW_R_OPT_NAME-2 "標準受光光学ユニット2|Standard receiving optical unit # 2"
*HW_R_OPT_NAME-3 "標準受光スリットボックス2|Standard receiving slit box # 2"
*HW_R_OPT_NAME-4 "標準アッテネータ|Standard Attenuator"
*HW_R_OPT_NAME-5 "Cu Kβ|Cu K-beta"
*HW_R_OPT_NAME-6 "調整用受光スリット|Alignment receiving slit"
*HW_SAMPLE_HOLDER_ID "SMP0021"
*HW_SAMPLE_HOLDER_NAME "χφZクレードル|Chi phi Z cradle"
*HW_XG_CURRENT_MAX "50"
*HW_XG_CURRENT_MIN "2"
*HW_XG_CURRENT_RESOLUTION "1"
*HW_XG_CURRENT_UNIT "mA"
*HW_XG_FOCUS "1mm x 10mm"
*HW_XG_FOCUS_TYPE "Normal"
*HW_XG_ID "1200"
*HW_XG_NAME "3kW 封入管(ID:1200)|3kW Sealed tube(ID:1200)"
*HW_XG_TARGET_ATOMIC_NUMBER "29.0000000000"
*HW_XG_TARGET_NAME "Cu"
*HW_XG_TYPE "Hermetic"
*HW_XG_VOLTAGE_MAX "50"
*HW_XG_VOLTAGE_MIN "20"
*HW_XG_VOLTAGE_RESOLUTION "1"
*HW_XG_VOLTAGE_UNIT "kV"
*HW_XG_WATT_MAX "1.300"
*HW_XG_WATT_UNIT "kW"
*HW_XG_WAVE_LENGTH_ALPHA1 "1.540593"
*HW_XG_WAVE_LENGTH_ALPHA2 "1.544414"
*HW_XG_WAVE_LENGTH_BETA "1.392250"
*MEAS_COND_AXIS_NAME-0 "Theta/2-Theta"
*MEAS_COND_AXIS_NAME-1 "2-Theta"
*MEAS_COND_AXIS_NAME-2 "Omega"
*MEAS_COND_AXIS_NAME-3 "Chi"
*MEAS_COND_AXIS_NAME-4 "Phi"
*MEAS_COND_AXIS_NAME-5 "Z"
*MEAS_COND_AXIS_NAME-6 "2-Theta/Omega"
*MEAS_COND_AXIS_NAME-7 "2-ThetaChi"
*MEAS_COND_AXIS_NAME-8 "2-ThetaChi/Phi"
*MEAS_COND_AXIS_NAME-9 "Alpha"
*MEAS_COND_AXIS_NAME-10 "Beta"
*MEAS_COND_AXIS_NAME-11 "Theta_s"
*MEAS_COND_AXIS_NAME-12 "Theta_d"
*MEAS_COND_AXIS_NAME-13 "Ts"
*MEAS_COND_AXIS_NAME-14 "CBO selection slit"
*MEAS_COND_AXIS_NAME-15 "M"
*MEAS_COND_AXIS_NAME-16 "Incident parallel slit"
*MEAS_COND_AXIS_NAME-17 "Incident slit"
*MEAS_COND_AXIS_NAME-18 ""
*MEAS_COND_AXIS_NAME-19 "Zs"
*MEAS_COND_AXIS_NAME-20 "Incident monochromator"
*MEAS_COND_AXIS_NAME-21 "Length limiting slit"
*MEAS_COND_AXIS_NAME-22 "Center slit"
*MEAS_COND_AXIS_NAME-23 "Filter"
*MEAS_COND_AXIS_NAME-24 "Receiving slit # 1"
*MEAS_COND_AXIS_NAME-25 "Receiving slit # 2"
*MEAS_COND_AXIS_NAME-26 "Receiving optical device"
*MEAS_COND_AXIS_NAME-27 "Receiving parallel slit"
*MEAS_COND_AXIS_NAME-28 "Alignment receiving slit"
*MEAS_COND_AXIS_NAME-29 ""
*MEAS_COND_AXIS_NAME-30 ""
*MEAS_COND_AXIS_NAME-31 "Zd"
*MEAS_COND_AXIS_NAME-32 "Attenuator"
*MEAS_COND_AXIS_NAME-33 "Diffracted beam monochromator"
*MEAS_COND_AXIS_NAME-34 "Monochromator slit"
*MEAS_COND_AXIS_NAME-35 "2-ThetaB"
*MEAS_COND_AXIS_NAME-36 ""
*MEAS_COND_AXIS_NAME-37 ""
*MEAS_COND_AXIS_NAME-38 "Primary beam"
*MEAS_COND_AXIS_NAME-39 "PHA"
*MEAS_COND_AXIS_NAME_INTERNAL-0 "TwoThetaTheta"
*MEAS_COND_AXIS_NAME_INTERNAL-1 "TwoTheta"
*MEAS_COND_AXIS_NAME_INTERNAL-2 "Omega"
*MEAS_COND_AXIS_NAME_INTERNAL-3 "Chi"
*MEAS_COND_AXIS_NAME_INTERNAL-4 "Phi"
*MEAS_COND_AXIS_NAME_INTERNAL-5 "Z"
*MEAS_COND_AXIS_NAME_INTERNAL-6 "TwoThetaOmega"
*MEAS_COND_AXIS_NAME_INTERNAL-7 "TwoThetaChi"
*MEAS_COND_AXIS_NAME_INTERNAL-8 "TwoThetaChiPhi"
*MEAS_COND_AXIS_NAME_INTERNAL-9 "Alpha"
*MEAS_COND_AXIS_NAME_INTERNAL-10 "Beta"
*MEAS_COND_AXIS_NAME_INTERNAL-11 "ThetaS"
*MEAS_COND_AXIS_NAME_INTERNAL-12 "ThetaD"
*MEAS_COND_AXIS_NAME_INTERNAL-13 "Ts"
*MEAS_COND_AXIS_NAME_INTERNAL-14 "CBO"
*MEAS_COND_AXIS_NAME_INTERNAL-15 "CBO-M"
*MEAS_COND_AXIS_NAME_INTERNAL-16 "IncidentSollerSlit"
*MEAS_COND_AXIS_NAME_INTERNAL-17 "IncidentSlitBox"
*MEAS_COND_AXIS_NAME_INTERNAL-18 "IncidentSlitBox-_Axis"
*MEAS_COND_AXIS_NAME_INTERNAL-19 "Zs"
*MEAS_COND_AXIS_NAME_INTERNAL-20 "IncidentMonochromator"
*MEAS_COND_AXIS_NAME_INTERNAL-21 "IncidentAxdSlit"
*MEAS_COND_AXIS_NAME_INTERNAL-22 "CenterSlit"
*MEAS_COND_AXIS_NAME_INTERNAL-23 "Filter"
*MEAS_COND_AXIS_NAME_INTERNAL-24 "ReceivingSlitBox1"
*MEAS_COND_AXIS_NAME_INTERNAL-25 "ReceivingSlitBox2"
*MEAS_COND_AXIS_NAME_INTERNAL-26 "ReceivingOptics"
*MEAS_COND_AXIS_NAME_INTERNAL-27 "ReceivingSollerSlit"
*MEAS_COND_AXIS_NAME_INTERNAL-28 "ReceivingAxdSlit"
*MEAS_COND_AXIS_NAME_INTERNAL-29 "ReceivingSlitBox1-_Axis"
*MEAS_COND_AXIS_NAME_INTERNAL-30 "ReceivingSlitBox2-_Axis"
*MEAS_COND_AXIS_NAME_INTERNAL-31 "ReceivingSlitBox2-Zd"
*MEAS_COND_AXIS_NAME_INTERNAL-32 "Attenuator"
*MEAS_COND_AXIS_NAME_INTERNAL-33 "CounterMonochromator"
*MEAS_COND_AXIS_NAME_INTERNAL-34 "CounterSlit"
*MEAS_COND_AXIS_NAME_INTERNAL-35 "TwoThetaB"
*MEAS_COND_AXIS_NAME_INTERNAL-36 "AlphaR"
*MEAS_COND_AXIS_NAME_INTERNAL-37 "BetaR"
*MEAS_COND_AXIS_NAME_INTERNAL-38 "IncidentPrimary"
*MEAS_COND_AXIS_NAME_INTERNAL-39 "PHA"
*MEAS_COND_AXIS_NAME_MAGICNO-0 "83951616.0000000000"
*MEAS_COND_AXIS_NAME_MAGICNO-1 "268632064.0000000000"
*MEAS_COND_AXIS_NAME_MAGICNO-2 "268500992.0000000000"
*MEAS_COND_AXIS_NAME_MAGICNO-3 "268500992.0000000000"
*MEAS_COND_AXIS_NAME_MAGICNO-4 "268500992.0000000000"
*MEAS_COND_AXIS_NAME_MAGICNO-5 "285278208.0000000000"
*MEAS_COND_AXIS_NAME_MAGICNO-6 "83951616.0000000000"
*MEAS_COND_AXIS_NAME_MAGICNO-7 "268632064.0000000000"
*MEAS_COND_AXIS_NAME_MAGICNO-8 "83951616.0000000000"
*MEAS_COND_AXIS_NAME_MAGICNO-9 "17039360.0000000000"
*MEAS_COND_AXIS_NAME_MAGICNO-10 "17039360.0000000000"
*MEAS_COND_AXIS_NAME_MAGICNO-11 "131072.0000000000"
*MEAS_COND_AXIS_NAME_MAGICNO-12 "131072.0000000000"
*MEAS_COND_AXIS_NAME_MAGICNO-13 "318898176.0000000000"
*MEAS_COND_AXIS_NAME_MAGICNO-14 "20971521.0000000000"
*MEAS_COND_AXIS_NAME_MAGICNO-15 "285343744.0000000000"
*MEAS_COND_AXIS_NAME_MAGICNO-16 "20971521.0000000000"
*MEAS_COND_AXIS_NAME_MAGICNO-17 "22020097.0000000000"
*MEAS_COND_AXIS_NAME_MAGICNO-18 "25165824.0000000000"
*MEAS_COND_AXIS_NAME_MAGICNO-19 "318898176.0000000000"
*MEAS_COND_AXIS_NAME_MAGICNO-20 "1.0000000000"
*MEAS_COND_AXIS_NAME_MAGICNO-21 "20971521.0000000000"
*MEAS_COND_AXIS_NAME_MAGICNO-22 "20971521.0000000000"
*MEAS_COND_AXIS_NAME_MAGICNO-23 "20971521.0000000000"
*MEAS_COND_AXIS_NAME_MAGICNO-24 "23068673.0000000000"
*MEAS_COND_AXIS_NAME_MAGICNO-25 "23068673.0000000000"
*MEAS_COND_AXIS_NAME_MAGICNO-26 "20971521.0000000000"
*MEAS_COND_AXIS_NAME_MAGICNO-27 "20971521.0000000000"
*MEAS_COND_AXIS_NAME_MAGICNO-28 "20971521.0000000000"
*MEAS_COND_AXIS_NAME_MAGICNO-29 "25165824.0000000000"
*MEAS_COND_AXIS_NAME_MAGICNO-30 "25165824.0000000000"
*MEAS_COND_AXIS_NAME_MAGICNO-31 "285343744.0000000000"
*MEAS_COND_AXIS_NAME_MAGICNO-32 "17301505.0000000000"
*MEAS_COND_AXIS_NAME_MAGICNO-33 "20971521.0000000000"
*MEAS_COND_AXIS_NAME_MAGICNO-34 "20971521.0000000000"
*MEAS_COND_AXIS_NAME_MAGICNO-35 "17039360.0000000000"
*MEAS_COND_AXIS_NAME_MAGICNO-36 "8388608.0000000000"
*MEAS_COND_AXIS_NAME_MAGICNO-37 "8388608.0000000000"
*MEAS_COND_AXIS_NAME_MAGICNO-38 "20971521.0000000000"
*MEAS_COND_AXIS_NAME_MAGICNO-39 "0.0000000000"
*MEAS_COND_AXIS_OFFSET-0 "-"
*MEAS_COND_AXIS_OFFSET-1 "-0.1015000000"
*MEAS_COND_AXIS_OFFSET-2 "-0.0103000000"
*MEAS_COND_AXIS_OFFSET-3 "0.0000000000"
*MEAS_COND_AXIS_OFFSET-4 "0.0000000000"
*MEAS_COND_AXIS_OFFSET-5 "-"
*MEAS_COND_AXIS_OFFSET-6 "-"
*MEAS_COND_AXIS_OFFSET-7 "0.0000000000"
*MEAS_COND_AXIS_OFFSET-8 "-"
*MEAS_COND_AXIS_OFFSET-9 "-"
*MEAS_COND_AXIS_OFFSET-10 "-"
*MEAS_COND_AXIS_OFFSET-11 "-0.0103000000"
*MEAS_COND_AXIS_OFFSET-12 "-0.0912000000"
*MEAS_COND_AXIS_OFFSET-13 "-"
*MEAS_COND_AXIS_OFFSET-14 "-"
*MEAS_COND_AXIS_OFFSET-15 "-"
*MEAS_COND_AXIS_OFFSET-16 "-"
*MEAS_COND_AXIS_OFFSET-17 "-"
*MEAS_COND_AXIS_OFFSET-18 "-"
*MEAS_COND_AXIS_OFFSET-19 "-"
*MEAS_COND_AXIS_OFFSET-20 "-"
*MEAS_COND_AXIS_OFFSET-21 "-"
*MEAS_COND_AXIS_OFFSET-22 "-"
*MEAS_COND_AXIS_OFFSET-23 "-"
*MEAS_COND_AXIS_OFFSET-24 "-"
*MEAS_COND_AXIS_OFFSET-25 "-"
*MEAS_COND_AXIS_OFFSET-26 "-"
*MEAS_COND_AXIS_OFFSET-27 "-"
*MEAS_COND_AXIS_OFFSET-28 "-"
*MEAS_COND_AXIS_OFFSET-29 "-"
*MEAS_COND_AXIS_OFFSET-30 "-"
*MEAS_COND_AXIS_OFFSET-31 "-"
*MEAS_COND_AXIS_OFFSET-32 "-"
*MEAS_COND_AXIS_OFFSET-33 "-"
*MEAS_COND_AXIS_OFFSET-34 "-"
*MEAS_COND_AXIS_OFFSET-35 "-"
*MEAS_COND_AXIS_OFFSET-36 "0.0000000000"
*MEAS_COND_AXIS_OFFSET-37 "0.0000000000"
*MEAS_COND_AXIS_OFFSET-38 "-"
*MEAS_COND_AXIS_OFFSET-39 "-"
*MEAS_COND_AXIS_POSITION-0 "0.0000000000"
*MEAS_COND_AXIS_POSITION-1 "0.0000000000"
*MEAS_COND_AXIS_POSITION-2 "0.0000000000"
*MEAS_COND_AXIS_POSITION-3 "0.0000000000"
*MEAS_COND_AXIS_POSITION-4 "0.0000000000"
*MEAS_COND_AXIS_POSITION-5 "-0.0245000000"
*MEAS_COND_AXIS_POSITION-6 "0.0000000000"
*MEAS_COND_AXIS_POSITION-7 "0.0000000000"
*MEAS_COND_AXIS_POSITION-8 "0.0000000000"
*MEAS_COND_AXIS_POSITION-9 "90.0000000000"
*MEAS_COND_AXIS_POSITION-10 "0.0000000000"
*MEAS_COND_AXIS_POSITION-11 "0.0000000000"
*MEAS_COND_AXIS_POSITION-12 "0.0000000000"
*MEAS_COND_AXIS_POSITION-13 "0.9465000000"
*MEAS_COND_AXIS_POSITION-14 "BB"
*MEAS_COND_AXIS_POSITION-15 "0.0000000000"
*MEAS_COND_AXIS_POSITION-16 "Soller_slit_5.0deg"
*MEAS_COND_AXIS_POSITION-17 "2/3deg"
*MEAS_COND_AXIS_POSITION-18 "2.2088000000"
*MEAS_COND_AXIS_POSITION-19 "0.4681300000"
*MEAS_COND_AXIS_POSITION-20 "0.0000000000"
*MEAS_COND_AXIS_POSITION-21 "10.0mm"
*MEAS_COND_AXIS_POSITION-22 "None"
*MEAS_COND_AXIS_POSITION-23 "Cu_K-beta"
*MEAS_COND_AXIS_POSITION-24 "20.000mm"
*MEAS_COND_AXIS_POSITION-25 "20.000mm"
*MEAS_COND_AXIS_POSITION-26 "No_unit"
*MEAS_COND_AXIS_POSITION-27 "Soller_slit_5.0deg"
*MEAS_COND_AXIS_POSITION-28 "None"
*MEAS_COND_AXIS_POSITION-29 "20.0000000000"
*MEAS_COND_AXIS_POSITION-30 "20.0000000000"
*MEAS_COND_AXIS_POSITION-31 "-0.0565600000"
*MEAS_COND_AXIS_POSITION-32 "Open"
*MEAS_COND_AXIS_POSITION-33 "None"
*MEAS_COND_AXIS_POSITION-34 "None"
*MEAS_COND_AXIS_POSITION-35 "0.0000000000"
*MEAS_COND_AXIS_POSITION-36 "0.3340000000"
*MEAS_COND_AXIS_POSITION-37 "0.0000000000"
*MEAS_COND_AXIS_POSITION-38 "None"
*MEAS_COND_AXIS_POSITION-39 "39.0000000000"
*MEAS_COND_AXIS_UNIT-0 "deg"
*MEAS_COND_AXIS_UNIT-1 "deg"
*MEAS_COND_AXIS_UNIT-2 "deg"
*MEAS_COND_AXIS_UNIT-3 "deg"
*MEAS_COND_AXIS_UNIT-4 "deg"
*MEAS_COND_AXIS_UNIT-5 "mm"
*MEAS_COND_AXIS_UNIT-6 "deg"
*MEAS_COND_AXIS_UNIT-7 "deg"
*MEAS_COND_AXIS_UNIT-8 "deg"
*MEAS_COND_AXIS_UNIT-9 "deg"
*MEAS_COND_AXIS_UNIT-10 "deg"
*MEAS_COND_AXIS_UNIT-11 "deg"
*MEAS_COND_AXIS_UNIT-12 "deg"
*MEAS_COND_AXIS_UNIT-13 "mm"
*MEAS_COND_AXIS_UNIT-14 ""
*MEAS_COND_AXIS_UNIT-15 "pulse"
*MEAS_COND_AXIS_UNIT-16 ""
*MEAS_COND_AXIS_UNIT-17 ""
*MEAS_COND_AXIS_UNIT-18 "mm"
*MEAS_COND_AXIS_UNIT-19 "mm"
*MEAS_COND_AXIS_UNIT-20 ""
*MEAS_COND_AXIS_UNIT-21 ""
*MEAS_COND_AXIS_UNIT-22 ""
*MEAS_COND_AXIS_UNIT-23 ""
*MEAS_COND_AXIS_UNIT-24 ""
*MEAS_COND_AXIS_UNIT-25 ""
*MEAS_COND_AXIS_UNIT-26 ""
*MEAS_COND_AXIS_UNIT-27 ""
*MEAS_COND_AXIS_UNIT-28 ""
*MEAS_COND_AXIS_UNIT-29 "mm"
*MEAS_COND_AXIS_UNIT-30 "mm"
*MEAS_COND_AXIS_UNIT-31 "mm"
*MEAS_COND_AXIS_UNIT-32 ""
*MEAS_COND_AXIS_UNIT-33 ""
*MEAS_COND_AXIS_UNIT-34 ""
*MEAS_COND_AXIS_UNIT-35 "deg"
*MEAS_COND_AXIS_UNIT-36 "deg"
*MEAS_COND_AXIS_UNIT-37 "deg"
*MEAS_COND_AXIS_UNIT-38 ""
*MEAS_COND_AXIS_UNIT-39 "div"
*MEAS_COND_COUNTER_CNTLOSS_CORR "0.0000000000"
*MEAS_COND_COUNTER_PHABASE "39.0000000000"
*MEAS_COND_COUNTER_PHAWINDOW "9.0000000000"
*MEAS_COND_COUNTER_PHA_UNIT "div"
*MEAS_COND_COUNTER_TAUDIFF "0.2500000000"
*MEAS_COND_COUNTER_TAUINT "0.7500000000"
*MEAS_COND_IRRADIATION_MODE "OFF"
*MEAS_COND_IRRADIATION_WIDTH ""
*MEAS_COND_OPT_ATTR "Bragg-Brentano focusing"
*MEAS_COND_OPT_NAME "@BB focusing"
*MEAS_COND_UNSYMMETRIC_MODE "OFF"
*MEAS_COND_XG_CURRENT "30.0000000000"
*MEAS_COND_XG_VOLTAGE "40.0000000000"
*MEAS_COND_XG_WAVE_TYPE "Ka"
*MEAS_DATA_COUNT "8001.0000000000"
*MEAS_SCAN_AXIS_X "2-Theta/Omega"
*MEAS_SCAN_AXIS_X_INTERNAL "TwoThetaOmega"
*MEAS_SCAN_END_TIME "02/23/22 08:44:59"
*MEAS_SCAN_MODE "CONTINUOUS"
*MEAS_SCAN_MONITOR "0"
*MEAS_SCAN_RESOLUTION_X "0.0002"
*MEAS_SCAN_SPEED "1.508742"
*MEAS_SCAN_SPEED_UNIT "deg/min"
*MEAS_SCAN_SPEED_USER "1.500000"
*MEAS_SCAN_START "20.0000000000"
*MEAS_SCAN_START_TIME "02/23/22 07:48:53"
*MEAS_SCAN_STEP "0.0100000000"
*MEAS_SCAN_STOP "100.0000000000"
*MEAS_SCAN_UNIT_X "deg"
*MEAS_SCAN_UNIT_Y "counts"
*RAS_HEADER_END
*RAS_INT_START
20.0000 864.0000 1.0000
20.0600 840.0000 1.0000
20.1200 856.0000 1.0000
20.1800 845.0000 1.0000
20.2400 827.0000 1.0000
20.3000 788.0000 1.0000
20.3600 828.0000 1.0000
20.4200 784.0000 1.0000
20.4800 780.0000 1.0000
20.5400 823.0000 1.0000
20.6000 823.0000 1.0000
20.6600 783.0000 1.0000
20.7200 818.0000 1.0000
20.7800 741.0000 1.0000
20.8400 775.0000 1.0000
20.9000 844.0000 1.0000
20.9600 763.0000 1.0000
21.0200 787.0000 1.0000
21.0800 784.0000 1.0000
21.1400 770.0000 1.0000
21.2000 750.0000 1.0000
21.2600 776.0000 1.0000
21.3200 718.0000 1.0000
21.3800 770.0000 1.0000
21.4400 743.0000 1.0000
21.5000 743.0000 1.0000
21.5600 762.0000 1.0000
21.6200 723.0000 1.0000
21.6800 749.0000 1.0000
21.7400 746.0000 1.0000
21.8000 718.0000 1.0000
21.8600 752.0000 1.0000
21.9200 745.0000 1.0000
21.9800 734.0000 1.0000
22.0400 711.0000 1.0000
22.1000 738.0000 1.0000
22.1600 691.0000 1.0000
22.2200 703.0000 1.0000
22.2800 721.0000 1.0000
22.3400 703.0000 1.0000
22.4000 687.0000 1.0000
22.4600 674.0000 1.0000
22.5200 757.0000 1.0000
22.5800 704.0000 1.0000
22.6400 715.0000 1.0000
22.7000 705.0000 1.0000
22.7600 693.0000 1.0000
22.8200 705.0000 1.0000
22.8800 680.0000 1.0000
22.9400 713.0000 1.0000
23.0000 693.0000 1.0000
23.0600 627.0000 1.0000
23.1200 673.0000 1.0000
23.1800 659.0000 1.0000
23.2400 641.0000 1.0000
23.3000 642.0000 1.0000
23.3600 656.0000 1.0000
23.4200 671.0000 1.0000
23.4800 667.0000 1.0000
23.5400 631.0000 1.0000
23.6000 687.0000 1.0000
23.6600 615.0000 1.0000
23.7200 661.0000 1.0000
23.7800 680.0000 1.0000
23.8400 630.0000 1.0000
23.9000 618.0000 1.0000
23.9600 624.0000 1.0000
24.0200 624.0000 1.0000
24.0800 652.0000 1.0000
24.1400 594.0000 1.0000
24.2000 613.0000 1.0000
24.2600 616.0000 1.0000
24.3200 611.0000 1.0000
24.3800 617.0000 1.0000
24.4400 663.0000 1.0000
24.5000 681.0000 1.0000
24.5600 671.0000 1.0000
24.6200 661.0000 1.0000
24.6800 615.0000 1.0000
24.7400 630.0000 1.0000
24.8000 605.0000 1.0000
24.8600 636.0000 1.0000
24.9200 634.0000 1.0000
24.9800 608.0000 1.0000
25.0400 612.0000 1.0000
25.1000 598.0000 1.0000
25.1600 608.0000 1.0000
25.2200 611.0000 1.0000
25.2800 610.0000 1.0000
25.3400 615.0000 1.0000
25.4000 601.0000 1.0000
25.4600 559.0000 1.0000
25.5200 602.0000 1.0000
25.5800 608.0000 1.0000
25.6400 569.0000 1.0000
25.7000 607.0000 1.0000
25.7600 613.0000 1.0000
25.8200 596.0000 1.0000
25.8800 599.0000 1.0000
25.9400 617.0000 1.0000
26.0000 590.0000 1.0000
26.0600 623.0000 1.0000
26.1200 662.0000 1.0000
26.1800 640.0000 1.0000
26.2400 600.0000 1.0000
26.3000 574.0000 1.0000
26.3600 624.0000 1.0000
26.4200 562.0000 1.0000
26.4800 620.0000 1.0000
26.5400 593.0000 1.0000
26.6000 548.0000 1.0000
26.6600 590.0000 1.0000
26.7200 587.0000 1.0000
26.7800 596.0000 1.0000
26.8400 596.0000 1.0000
26.9000 557.0000 1.0000
26.9600 571.0000 1.0000
27.0200 636.0000 1.0000
27.0800 697.0000 1.0000
27.1400 972.0000 1.0000
27.2000 2534.0000 1.0000
27.2600 2080.0000 1.0000
27.3200 1627.0000 1.0000
27.3800 1063.0000 1.0000
27.4400 924.0000 1.0000
27.5000 703.0000 1.0000
27.5600 616.0000 1.0000
27.6200 552.0000 1.0000
27.6800 535.0000 1.0000
27.7400 535.0000 1.0000
27.8000 488.0000 1.0000
27.8600 545.0000 1.0000
27.9200 508.0000 1.0000
27.9800 497.0000 1.0000
28.0400 497.0000 1.0000
28.1000 517.0000 1.0000
28.1600 549.0000 1.0000
28.2200 535.0000 1.0000
28.2800 604.0000 1.0000
28.3400 776.0000 1.0000
28.4000 600.0000 1.0000
28.4600 628.0000 1.0000
28.5200 563.0000 1.0000
28.5800 550.0000 1.0000
28.6400 524.0000 1.0000
28.7000 521.0000 1.0000
28.7600 490.0000 1.0000
28.8200 544.0000 1.0000
28.8800 472.0000 1.0000
28.9400 502.0000 1.0000
29.0000 502.0000 1.0000
29.0600 503.0000 1.0000
29.1200 480.0000 1.0000
29.1800 498.0000 1.0000
29.2400 480.0000 1.0000
29.3000 485.0000 1.0000
29.3600 486.0000 1.0000
29.4200 491.0000 1.0000
29.4800 519.0000 1.0000
29.5400 452.0000 1.0000
29.6000 482.0000 1.0000
29.6600 496.0000 1.0000
29.7200 494.0000 1.0000
29.7800 489.0000 1.0000
29.8400 490.0000 1.0000
29.9000 474.0000 1.0000
29.9600 475.0000 1.0000
30.0200 482.0000 1.0000
30.0800 515.0000 1.0000
30.1400 543.0000 1.0000
30.2000 512.0000 1.0000
30.2600 481.0000 1.0000
30.3200 530.0000 1.0000
30.3800 658.0000 1.0000
30.4400 597.0000 1.0000
30.5000 593.0000 1.0000
30.5600 596.0000 1.0000
30.6200 590.0000 1.0000
30.6800 604.0000 1.0000
30.7400 602.0000 1.0000
30.8000 561.0000 1.0000
30.8600 634.0000 1.0000
30.9200 599.0000 1.0000
30.9800 570.0000 1.0000
31.0400 596.0000 1.0000
31.1000 643.0000 1.0000
31.1600 741.0000 1.0000
31.2200 879.0000 1.0000
31.2800 1315.0000 1.0000
31.3400 2226.0000 1.0000
31.4000 3984.0000 1.0000
31.4600 26595.0000 1.0000
31.5200 11093.0000 1.0000
31.5800 9910.0000 1.0000
31.6400 5649.0000 1.0000
31.7000 4402.0000 1.0000
31.7600 3311.0000 1.0000
31.8200 1908.0000 1.0000
31.8800 1238.0000 1.0000
31.9400 786.0000 1.0000
32.0000 616.0000 1.0000
32.0600 598.0000 1.0000
32.1200 540.0000 1.0000
32.1800 489.0000 1.0000
32.2400 492.0000 1.0000
32.3000 483.0000 1.0000
32.3600 476.0000 1.0000
32.4200 496.0000 1.0000
32.4800 515.0000 1.0000
32.5400 505.0000 1.0000
32.6000 485.0000 1.0000
32.6600 489.0000 1.0000
32.7200 467.0000 1.0000
32.7800 455.0000 1.0000
32.8400 465.0000 1.0000
32.9000 441.0000 1.0000
32.9600 413.0000 1.0000
33.0200 437.0000 1.0000
33.0800 471.0000 1.0000
33.1400 454.0000 1.0000
33.2000 446.0000 1.0000
33.2600 474.0000 1.0000
33.3200 438.0000 1.0000
33.3800 402.0000 1.0000
33.4400 429.0000 1.0000
33.5000 412.0000 1.0000
33.5600 453.0000 1.0000
33.6200 380.0000 1.0000
33.6800 448.0000 1.0000
33.7400 457.0000 1.0000
33.8000 423.0000 1.0000
33.8600 388.0000 1.0000
33.9200 389.0000 1.0000
33.9800 377.0000 1.0000
34.0400 415.0000 1.0000
34.1000 402.0000 1.0000
34.1600 413.0000 1.0000
34.2200 410.0000 1.0000
34.2800 446.0000 1.0000
34.3400 391.0000 1.0000
34.4000 430.0000 1.0000
34.4600 413.0000 1.0000
34.5200 387.0000 1.0000
34.5800 366.0000 1.0000
34.6400 380.0000 1.0000
34.7000 374.0000 1.0000
34.7600 389.0000 1.0000
34.8200 359.0000 1.0000
34.8800 383.0000 1.0000
34.9400 376.0000 1.0000
35.0000 374.0000 1.0000
35.0600 352.0000 1.0000
35.1200 351.0000 1.0000
35.1800 388.0000 1.0000
35.2400 359.0000 1.0000
35.3000 366.0000 1.0000
35.3600 355.0000 1.0000
35.4200 340.0000 1.0000
35.4800 336.0000 1.0000
35.5400 336.0000 1.0000
35.6000 352.0000 1.0000
35.6600 332.0000 1.0000
35.7200 354.0000 1.0000
35.7800 370.0000 1.0000
35.8400 343.0000 1.0000
35.9000 319.0000 1.0000
35.9600 325.0000 1.0000
36.0200 359.0000 1.0000
36.0800 313.0000 1.0000
36.1400 350.0000 1.0000
36.2000 351.0000 1.0000
36.2600 355.0000 1.0000
36.3200 346.0000 1.0000
36.3800 332.0000 1.0000
36.4400 341.0000 1.0000
36.5000 332.0000 1.0000
36.5600 340.0000 1.0000
36.6200 321.0000 1.0000
36.6800 312.0000 1.0000
36.7400 338.0000 1.0000
36.8000 342.0000 1.0000
36.8600 307.0000 1.0000
36.9200 350.0000 1.0000
36.9800 331.0000 1.0000
37.0400 304.0000 1.0000
37.1000 316.0000 1.0000
37.1600 326.0000 1.0000
37.2200 333.0000 1.0000
37.2800 326.0000 1.0000
37.3400 354.0000 1.0000
37.4000 337.0000 1.0000
37.4600 329.0000 1.0000
37.5200 313.0000 1.0000
37.5800 316.0000 1.0000
37.6400 284.0000 1.0000
37.7000 276.0000 1.0000
37.7600 336.0000 1.0000
37.8200 309.0000 1.0000
37.8800 286.0000 1.0000
37.9400 332.0000 1.0000
38.0000 301.0000 1.0000
38.0600 296.0000 1.0000
38.1200 349.0000 1.0000
38.1800 320.0000 1.0000
38.2400 299.0000 1.0000
38.3000 289.0000 1.0000
38.3600 305.0000 1.0000
38.4200 275.0000 1.0000
38.4800 269.0000 1.0000
38.5400 279.0000 1.0000
38.6000 304.0000 1.0000
38.6600 305.0000 1.0000
38.7200 270.0000 1.0000
38.7800 293.0000 1.0000
38.8400 288.0000 1.0000
38.9000 275.0000 1.0000
38.9600 292.0000 1.0000
39.0200 284.0000 1.0000
39.0800 264.0000 1.0000
39.1400 302.0000 1.0000
39.2000 286.0000 1.0000
39.2600 312.0000 1.0000
39.3200 323.0000 1.0000
39.3800 282.0000 1.0000
39.4400 259.0000 1.0000
39.5000 262.0000 1.0000
39.5600 252.0000 1.0000
39.6200 283.0000 1.0000
39.6800 264.0000 1.0000
39.7400 292.0000 1.0000
39.8000 292.0000 1.0000
39.8600 280.0000 1.0000
39.9200 242.0000 1.0000
39.9800 270.0000 1.0000
40.0400 293.0000 1.0000
40.1000 290.0000 1.0000
40.1600 299.0000 1.0000
40.2200 262.0000 1.0000
40.2800 258.0000 1.0000
40.3400 260.0000 1.0000
40.4000 285.0000 1.0000
40.4600 292.0000 1.0000
40.5200 299.0000 1.0000
40.5800 305.0000 1.0000
40.6400 267.0000 1.0000
40.7000 278.0000 1.0000
40.7600 321.0000 1.0000
40.8200 291.0000 1.0000
40.8800 256.0000 1.0000
40.9400 268.0000 1.0000
41.0000 272.0000 1.0000
41.0600 294.0000 1.0000
41.1200 271.0000 1.0000
41.1800 257.0000 1.0000
41.2400 269.0000 1.0000
41.3000 274.0000 1.0000
41.3600 254.0000 1.0000
41.4200 271.0000 1.0000
41.4800 256.0000 1.0000
41.5400 271.0000 1.0000
41.6000 258.0000 1.0000
41.6600 235.0000 1.0000
41.7200 270.0000 1.0000
41.7800 263.0000 1.0000
41.8400 231.0000 1.0000
41.9000 253.0000 1.0000
41.9600 245.0000 1.0000
42.0200 243.0000 1.0000
42.0800 231.0000 1.0000
42.1400 256.0000 1.0000
42.2000 233.0000 1.0000
42.2600 248.0000 1.0000
42.3200 246.0000 1.0000
42.3800 240.0000 1.0000
42.4400 223.0000 1.0000
42.5000 255.0000 1.0000
42.5600 264.0000 1.0000
42.6200 242.0000 1.0000
42.6800 217.0000 1.0000
42.7400 232.0000 1.0000
42.8000 240.0000 1.0000
42.8600 231.0000 1.0000
42.9200 230.0000 1.0000
42.9800 240.0000 1.0000
43.0400 236.0000 1.0000
43.1000 251.0000 1.0000
43.1600 240.0000 1.0000
43.2200 244.0000 1.0000
43.2800 255.0000 1.0000
43.3400 263.0000 1.0000
43.4000 232.0000 1.0000
43.4600 230.0000 1.0000
43.5200 252.0000 1.0000
43.5800 275.0000 1.0000
43.6400 258.0000 1.0000
43.7000 255.0000 1.0000
43.7600 253.0000 1.0000
43.8200 276.0000 1.0000
43.8800 269.0000 1.0000
43.9400 240.0000 1.0000
44.0000 302.0000 1.0000
44.0600 261.0000 1.0000
44.1200 256.0000 1.0000
44.1800 249.0000 1.0000
44.2400 270.0000 1.0000
44.3000 268.0000 1.0000
44.3600 294.0000 1.0000
44.4200 256.0000 1.0000
44.4800 274.0000 1.0000
44.5400 248.0000 1.0000
44.6000 293.0000 1.0000
44.6600 262.0000 1.0000
44.7200 281.0000 1.0000
44.7800 274.0000 1.0000
44.8400 258.0000 1.0000
44.9000 281.0000 1.0000
44.9600 345.0000 1.0000
45.0200 520.0000 1.0000
45.0800 1205.0000 1.0000
45.1400 1883.0000 1.0000
45.2000 2558.0000 1.0000
45.2600 2010.0000 1.0000
45.3200 4268.0000 1.0000
45.3800 2743.0000 1.0000
45.4400 3059.0000 1.0000
45.5000 1695.0000 1.0000
45.5600 1119.0000 1.0000
45.6200 639.0000 1.0000
45.6800 398.0000 1.0000
45.7400 276.0000 1.0000
45.8000 309.0000 1.0000
45.8600 270.0000 1.0000
45.9200 242.0000 1.0000
45.9800 286.0000 1.0000
46.0400 230.0000 1.0000
46.1000 232.0000 1.0000
46.1600 245.0000 1.0000
46.2200 235.0000 1.0000
46.2800 231.0000 1.0000
46.3400 252.0000 1.0000
46.4000 243.0000 1.0000
46.4600 230.0000 1.0000
46.5200 228.0000 1.0000
46.5800 212.0000 1.0000
46.6400 222.0000 1.0000
46.7000 237.0000 1.0000
46.7600 249.0000 1.0000
46.8200 243.0000 1.0000
46.8800 246.0000 1.0000
46.9400 224.0000 1.0000
47.0000 220.0000 1.0000
47.0600 218.0000 1.0000
47.1200 237.0000 1.0000
47.1800 220.0000 1.0000
47.2400 202.0000 1.0000
47.3000 223.0000 1.0000
47.3600 205.0000 1.0000
47.4200 215.0000 1.0000
47.4800 203.0000 1.0000
47.5400 207.0000 1.0000
47.6000 207.0000 1.0000
47.6600 223.0000 1.0000
47.7200 191.0000 1.0000
47.7800 219.0000 1.0000
47.8400 227.0000 1.0000
47.9000 173.0000 1.0000
47.9600 193.0000 1.0000
48.0200 226.0000 1.0000
48.0800 205.0000 1.0000
48.1400 219.0000 1.0000
48.2000 191.0000 1.0000
48.2600 236.0000 1.0000
48.3200 198.0000 1.0000
48.3800 229.0000 1.0000
48.4400 208.0000 1.0000
48.5000 192.0000 1.0000
48.5600 193.0000 1.0000
48.6200 198.0000 1.0000
48.6800 209.0000 1.0000
48.7400 205.0000 1.0000
48.8000 196.0000 1.0000
48.8600 210.0000 1.0000
48.9200 202.0000 1.0000
48.9800 190.0000 1.0000
49.0400 207.0000 1.0000
49.1000 192.0000 1.0000
49.1600 174.0000 1.0000
49.2200 208.0000 1.0000
49.2800 187.0000 1.0000
49.3400 190.0000 1.0000
49.4000 182.0000 1.0000
49.4600 209.0000 1.0000
49.5200 218.0000 1.0000
49.5800 204.0000 1.0000
49.6400 181.0000 1.0000
49.7000 223.0000 1.0000
49.7600 204.0000 1.0000
49.8200 177.0000 1.0000
49.8800 203.0000 1.0000
49.9400 188.0000 1.0000
50.0000 187.0000 1.0000
50.0600 176.0000 1.0000
50.1200 214.0000 1.0000
50.1800 213.0000 1.0000
50.2400 189.0000 1.0000
50.3000 170.0000 1.0000
50.3600 206.0000 1.0000
50.4200 227.0000 1.0000
50.4800 188.0000 1.0000
50.5400 209.0000 1.0000
50.6000 203.0000 1.0000
50.6600 174.0000 1.0000
50.7200 158.0000 1.0000
50.7800 174.0000 1.0000
50.8400 166.0000 1.0000
50.9000 187.0000 1.0000
50.9600 189.0000 1.0000
51.0200 180.0000 1.0000
51.0800 199.0000 1.0000
51.1400 189.0000 1.0000
51.2000 194.0000 1.0000
51.2600 168.0000 1.0000
51.3200 203.0000 1.0000
51.3800 204.0000 1.0000
51.4400 170.0000 1.0000
51.5000 186.0000 1.0000
51.5600 191.0000 1.0000
51.6200 169.0000 1.0000
51.6800 194.0000 1.0000
51.7400 204.0000 1.0000
51.8000 212.0000 1.0000
51.8600 159.0000 1.0000
51.9200 180.0000 1.0000
51.9800 176.0000 1.0000
52.0400 169.0000 1.0000
52.1000 187.0000 1.0000
52.1600 151.0000 1.0000
52.2200 196.0000 1.0000
52.2800 180.0000 1.0000
52.3400 169.0000 1.0000
52.4000 157.0000 1.0000
52.4600 187.0000 1.0000
52.5200 172.0000 1.0000
52.5800 192.0000 1.0000
52.6400 182.0000 1.0000
52.7000 181.0000 1.0000
52.7600 201.0000 1.0000
52.8200 188.0000 1.0000
52.8800 176.0000 1.0000
52.9400 193.0000 1.0000
53.0000 184.0000 1.0000
53.0600 147.0000 1.0000
53.1200 190.0000 1.0000
53.1800 190.0000 1.0000
53.2400 190.0000 1.0000
53.3000 162.0000 1.0000
53.3600 208.0000 1.0000
53.4200 203.0000 1.0000
53.4800 272.0000 1.0000
53.5400 706.0000 1.0000
53.6000 1247.0000 1.0000
53.6600 514.0000 1.0000
53.7200 1760.0000 1.0000
53.7800 901.0000 1.0000
53.8400 637.0000 1.0000
53.9000 566.0000 1.0000
53.9600 407.0000 1.0000
54.0200 268.0000 1.0000
54.0800 233.0000 1.0000
54.1400 201.0000 1.0000
54.2000 205.0000 1.0000
54.2600 197.0000 1.0000
54.3200 181.0000 1.0000
54.3800 173.0000 1.0000
54.4400 195.0000 1.0000
54.5000 185.0000 1.0000
54.5600 175.0000 1.0000
54.6200 178.0000 1.0000
54.6800 144.0000 1.0000
54.7400 177.0000 1.0000
54.8000 169.0000 1.0000
54.8600 177.0000 1.0000
54.9200 171.0000 1.0000
54.9800 170.0000 1.0000
55.0400 166.0000 1.0000
55.1000 156.0000 1.0000
55.1600 145.0000 1.0000
55.2200 201.0000 1.0000
55.2800 163.0000 1.0000
55.3400 161.0000 1.0000
55.4000 185.0000 1.0000
55.4600 174.0000 1.0000
55.5200 188.0000 1.0000
55.5800 164.0000 1.0000
55.6400 193.0000 1.0000
55.7000 190.0000 1.0000
55.7600 167.0000 1.0000
55.8200 189.0000 1.0000
55.8800 160.0000 1.0000
55.9400 183.0000 1.0000
56.0000 203.0000 1.0000
56.0600 205.0000 1.0000
56.1200 266.0000 1.0000
56.1800 421.0000 1.0000
56.2400 622.0000 1.0000
56.3000 990.0000 1.0000
56.3600 1219.0000 1.0000
56.4200 1116.0000 1.0000
56.4800 946.0000 1.0000
56.5400 995.0000 1.0000
56.6000 510.0000 1.0000
56.6600 425.0000 1.0000
56.7200 306.0000 1.0000
56.7800 225.0000 1.0000
56.8400 178.0000 1.0000
56.9000 187.0000 1.0000
56.9600 176.0000 1.0000
57.0200 133.0000 1.0000
57.0800 168.0000 1.0000
57.1400 163.0000 1.0000
57.2000 158.0000 1.0000
57.2600 147.0000 1.0000
57.3200 170.0000 1.0000
57.3800 163.0000 1.0000
57.4400 149.0000 1.0000
57.5000 150.0000 1.0000
57.5600 176.0000 1.0000
57.6200 149.0000 1.0000
57.6800 152.0000 1.0000
57.7400 183.0000 1.0000
57.8000 183.0000 1.0000
57.8600 133.0000 1.0000
57.9200 135.0000 1.0000
57.9800 155.0000 1.0000
58.0400 163.0000 1.0000
58.1000 140.0000 1.0000
58.1600 151.0000 1.0000
58.2200 165.0000 1.0000
58.2800 161.0000 1.0000
58.3400 162.0000 1.0000
58.4000 150.0000 1.0000
58.4600 136.0000 1.0000
58.5200 153.0000 1.0000
58.5800 159.0000 1.0000
58.6400 141.0000 1.0000
58.7000 168.0000 1.0000
58.7600 147.0000 1.0000
58.8200 121.0000 1.0000
58.8800 169.0000 1.0000
58.9400 162.0000 1.0000
59.0000 162.0000 1.0000
59.0600 158.0000 1.0000
59.1200 146.0000 1.0000
59.1800 155.0000 1.0000
59.2400 149.0000 1.0000
59.3000 139.0000 1.0000
59.3600 140.0000 1.0000
59.4200 157.0000 1.0000
59.4800 148.0000 1.0000
59.5400 154.0000 1.0000
59.6000 143.0000 1.0000
59.6600 152.0000 1.0000
59.7200 162.0000 1.0000
59.7800 132.0000 1.0000
59.8400 141.0000 1.0000
59.9000 150.0000 1.0000
59.9600 151.0000 1.0000
60.0200 163.0000 1.0000
60.0800 141.0000 1.0000
60.1400 125.0000 1.0000
60.2000 143.0000 1.0000
60.2600 152.0000 1.0000
60.3200 146.0000 1.0000
60.3800 142.0000 1.0000
60.4400 147.0000 1.0000
60.5000 154.0000 1.0000
60.5600 133.0000 1.0000
60.6200 137.0000 1.0000
60.6800 149.0000 1.0000
60.7400 153.0000 1.0000
60.8000 143.0000 1.0000
60.8600 164.0000 1.0000
60.9200 162.0000 1.0000
60.9800 142.0000 1.0000
61.0400 149.0000 1.0000
61.1000 180.0000 1.0000
61.1600 143.0000 1.0000
61.2200 143.0000 1.0000
61.2800 144.0000 1.0000
61.3400 162.0000 1.0000
61.4000 141.0000 1.0000
61.4600 144.0000 1.0000
61.5200 139.0000 1.0000
61.5800 137.0000 1.0000
61.6400 141.0000 1.0000
61.7000 146.0000 1.0000
61.7600 123.0000 1.0000
61.8200 129.0000 1.0000
61.8800 124.0000 1.0000
61.9400 148.0000 1.0000
62.0000 151.0000 1.0000
62.0600 146.0000 1.0000
62.1200 143.0000 1.0000
62.1800 147.0000 1.0000
62.2400 158.0000 1.0000
62.3000 146.0000 1.0000
62.3600 145.0000 1.0000
62.4200 129.0000 1.0000
62.4800 131.0000 1.0000
62.5400 151.0000 1.0000
62.6000 136.0000 1.0000
62.6600 135.0000 1.0000
62.7200 146.0000 1.0000
62.7800 145.0000 1.0000
62.8400 143.0000 1.0000
62.9000 127.0000 1.0000
62.9600 144.0000 1.0000
63.0200 129.0000 1.0000
63.0800 129.0000 1.0000
63.1400 147.0000 1.0000
63.2000 150.0000 1.0000
63.2600 106.0000 1.0000
63.3200 145.0000 1.0000
63.3800 129.0000 1.0000
63.4400 142.0000 1.0000
63.5000 122.0000 1.0000
63.5600 130.0000 1.0000
63.6200 150.0000 1.0000
63.6800 136.0000 1.0000
63.7400 136.0000 1.0000
63.8000 135.0000 1.0000
63.8600 135.0000 1.0000
63.9200 136.0000 1.0000
63.9800 126.0000 1.0000
64.0400 140.0000 1.0000
64.1000 137.0000 1.0000
64.1600 145.0000 1.0000
64.2200 150.0000 1.0000
64.2800 153.0000 1.0000
64.3400 154.0000 1.0000
64.4000 141.0000 1.0000
64.4600 151.0000 1.0000
64.5200 132.0000 1.0000
64.5800 155.0000 1.0000
64.6400 144.0000 1.0000
64.7000 141.0000 1.0000
64.7600 131.0000 1.0000
64.8200 150.0000 1.0000
64.8800 145.0000 1.0000
64.9400 140.0000 1.0000
65.0000 136.0000 1.0000
65.0600 153.0000 1.0000
65.1200 157.0000 1.0000
65.1800 139.0000 1.0000
65.2400 134.0000 1.0000
65.3000 160.0000 1.0000
65.3600 176.0000 1.0000
65.4200 146.0000 1.0000
65.4800 138.0000 1.0000
65.5400 153.0000 1.0000
65.6000 157.0000 1.0000
65.6600 163.0000 1.0000
65.7200 167.0000 1.0000
65.7800 187.0000 1.0000
65.8400 211.0000 1.0000
65.9000 235.0000 1.0000
65.9600 297.0000 1.0000
66.0200 495.0000 1.0000
66.0800 870.0000 1.0000
66.1400 660.0000 1.0000
66.2000 516.0000 1.0000
66.2600 657.0000 1.0000
66.3200 450.0000 1.0000
66.3800 297.0000 1.0000
66.4400 259.0000 1.0000
66.5000 200.0000 1.0000
66.5600 169.0000 1.0000
66.6200 170.0000 1.0000
66.6800 174.0000 1.0000
66.7400 169.0000 1.0000
66.8000 188.0000 1.0000
66.8600 201.0000 1.0000
66.9200 170.0000 1.0000
66.9800 181.0000 1.0000
67.0400 156.0000 1.0000
67.1000 163.0000 1.0000
67.1600 164.0000 1.0000
67.2200 157.0000 1.0000
67.2800 157.0000 1.0000
67.3400 150.0000 1.0000
67.4000 151.0000 1.0000
67.4600 174.0000 1.0000
67.5200 151.0000 1.0000
67.5800 156.0000 1.0000
67.6400 135.0000 1.0000
67.7000 130.0000 1.0000
67.7600 141.0000 1.0000
67.8200 130.0000 1.0000
67.8800 130.0000 1.0000
67.9400 136.0000 1.0000
68.0000 151.0000 1.0000
68.0600 154.0000 1.0000
68.1200 144.0000 1.0000
68.1800 128.0000 1.0000
68.2400 128.0000 1.0000
68.3000 143.0000 1.0000
68.3600 143.0000 1.0000
68.4200 153.0000 1.0000
68.4800 134.0000 1.0000
68.5400 145.0000 1.0000
68.6000 155.0000 1.0000
68.6600 136.0000 1.0000
68.7200 142.0000 1.0000
68.7800 136.0000 1.0000
68.8400 161.0000 1.0000
68.9000 138.0000 1.0000
68.9600 154.0000 1.0000
69.0200 143.0000 1.0000
69.0800 141.0000 1.0000
69.1400 136.0000 1.0000
69.2000 130.0000 1.0000
69.2600 149.0000 1.0000
69.3200 123.0000 1.0000
69.3800 129.0000 1.0000
69.4400 147.0000 1.0000
69.5000 143.0000 1.0000
69.5600 121.0000 1.0000
69.6200 137.0000 1.0000
69.6800 127.0000 1.0000
69.7400 143.0000 1.0000
69.8000 126.0000 1.0000
69.8600 154.0000 1.0000
69.9200 127.0000 1.0000
69.9800 151.0000 1.0000
70.0400 129.0000 1.0000
70.1000 142.0000 1.0000
70.1600 162.0000 1.0000
70.2200 144.0000 1.0000
70.2800 123.0000 1.0000
70.3400 146.0000 1.0000
70.4000 142.0000 1.0000
70.4600 140.0000 1.0000
70.5200 136.0000 1.0000
70.5800 144.0000 1.0000
70.6400 138.0000 1.0000
70.7000 125.0000 1.0000
70.7600 125.0000 1.0000
70.8200 139.0000 1.0000
70.8800 127.0000 1.0000
70.9400 133.0000 1.0000
71.0000 146.0000 1.0000
71.0600 123.0000 1.0000
71.1200 125.0000 1.0000
71.1800 122.0000 1.0000
71.2400 134.0000 1.0000
71.3000 127.0000 1.0000
71.3600 145.0000 1.0000
71.4200 141.0000 1.0000
71.4800 147.0000 1.0000
71.5400 161.0000 1.0000
71.6000 159.0000 1.0000
71.6600 143.0000 1.0000
71.7200 125.0000 1.0000
71.7800 120.0000 1.0000
71.8400 156.0000 1.0000
71.9000 125.0000 1.0000
71.9600 144.0000 1.0000
72.0200 129.0000 1.0000
72.0800 138.0000 1.0000
72.1400 139.0000 1.0000
72.2000 162.0000 1.0000
72.2600 147.0000 1.0000
72.3200 167.0000 1.0000
72.3800 174.0000 1.0000
72.4400 147.0000 1.0000
72.5000 150.0000 1.0000
72.5600 136.0000 1.0000
72.6200 152.0000 1.0000
72.6800 165.0000 1.0000
72.7400 189.0000 1.0000
72.8000 280.0000 1.0000
72.8600 269.0000 1.0000
72.9200 230.0000 1.0000
72.9800 196.0000 1.0000
73.0400 240.0000 1.0000
73.1000 185.0000 1.0000
73.1600 172.0000 1.0000
73.2200 173.0000 1.0000
73.2800 155.0000 1.0000
73.3400 172.0000 1.0000
73.4000 148.0000 1.0000
73.4600 170.0000 1.0000
73.5200 152.0000 1.0000
73.5800 156.0000 1.0000
73.6400 159.0000 1.0000
73.7000 154.0000 1.0000
73.7600 155.0000 1.0000
73.8200 141.0000 1.0000
73.8800 137.0000 1.0000
73.9400 133.0000 1.0000
74.0000 155.0000 1.0000
74.0600 152.0000 1.0000
74.1200 169.0000 1.0000
74.1800 177.0000 1.0000
74.2400 176.0000 1.0000
74.3000 186.0000 1.0000
74.3600 188.0000 1.0000
74.4200 163.0000 1.0000
74.4800 167.0000 1.0000
74.5400 185.0000 1.0000
74.6000 199.0000 1.0000
74.6600 163.0000 1.0000
74.7200 182.0000 1.0000
74.7800 224.0000 1.0000
74.8400 246.0000 1.0000
74.9000 355.0000 1.0000
74.9600 766.0000 1.0000
75.0200 800.0000 1.0000
75.0800 1210.0000 1.0000
75.1400 2494.0000 1.0000
75.2000 1560.0000 1.0000
75.2600 1210.0000 1.0000
75.3200 1585.0000 1.0000
75.3800 1378.0000 1.0000
75.4400 676.0000 1.0000
75.5000 519.0000 1.0000
75.5600 448.0000 1.0000
75.6200 257.0000 1.0000
75.6800 221.0000 1.0000
75.7400 171.0000 1.0000
75.8000 182.0000 1.0000
75.8600 164.0000 1.0000
75.9200 170.0000 1.0000
75.9800 143.0000 1.0000
76.0400 164.0000 1.0000
76.1000 173.0000 1.0000
76.1600 159.0000 1.0000
76.2200 160.0000 1.0000
76.2800 157.0000 1.0000
76.3400 148.0000 1.0000
76.4000 144.0000 1.0000
76.4600 154.0000 1.0000
76.5200 158.0000 1.0000
76.5800 148.0000 1.0000
76.6400 134.0000 1.0000
76.7000 148.0000 1.0000
76.7600 129.0000 1.0000
76.8200 133.0000 1.0000
76.8800 150.0000 1.0000
76.9400 150.0000 1.0000
77.0000 146.0000 1.0000
77.0600 163.0000 1.0000
77.1200 109.0000 1.0000
77.1800 124.0000 1.0000
77.2400 123.0000 1.0000
77.3000 136.0000 1.0000
77.3600 138.0000 1.0000
77.4200 148.0000 1.0000
77.4800 158.0000 1.0000
77.5400 154.0000 1.0000
77.6000 143.0000 1.0000
77.6600 116.0000 1.0000
77.7200 137.0000 1.0000
77.7800 138.0000 1.0000
77.8400 132.0000 1.0000
77.9000 145.0000 1.0000
77.9600 156.0000 1.0000
78.0200 139.0000 1.0000
78.0800 129.0000 1.0000
78.1400 130.0000 1.0000
78.2000 136.0000 1.0000
78.2600 148.0000 1.0000
78.3200 143.0000 1.0000
78.3800 141.0000 1.0000
78.4400 144.0000 1.0000
78.5000 145.0000 1.0000
78.5600 139.0000 1.0000
78.6200 122.0000 1.0000
78.6800 125.0000 1.0000
78.7400 167.0000 1.0000
78.8000 126.0000 1.0000
78.8600 132.0000 1.0000
78.9200 114.0000 1.0000
78.9800 135.0000 1.0000
79.0400 133.0000 1.0000
79.1000 147.0000 1.0000
79.1600 118.0000 1.0000
79.2200 125.0000 1.0000
79.2800 136.0000 1.0000
79.3400 132.0000 1.0000
79.4000 138.0000 1.0000
79.4600 119.0000 1.0000
79.5200 122.0000 1.0000
79.5800 125.0000 1.0000
79.6400 154.0000 1.0000
79.7000 130.0000 1.0000
79.7600 134.0000 1.0000
79.8200 159.0000 1.0000
79.8800 126.0000 1.0000
79.9400 141.0000 1.0000
80.0000 132.0000 1.0000
80.0600 143.0000 1.0000
80.1200 124.0000 1.0000
80.1800 131.0000 1.0000
80.2400 129.0000 1.0000
80.3000 161.0000 1.0000
80.3600 137.0000 1.0000
80.4200 138.0000 1.0000
80.4800 139.0000 1.0000
80.5400 144.0000 1.0000
80.6000 141.0000 1.0000
80.6600 139.0000 1.0000
80.7200 123.0000 1.0000
80.7800 130.0000 1.0000
80.8400 129.0000 1.0000
80.9000 148.0000 1.0000
80.9600 156.0000 1.0000
81.0200 139.0000 1.0000
81.0800 121.0000 1.0000
81.1400 142.0000 1.0000
81.2000 134.0000 1.0000
81.2600 142.0000 1.0000
81.3200 133.0000 1.0000
81.3800 137.0000 1.0000
81.4400 134.0000 1.0000
81.5000 131.0000 1.0000
81.5600 139.0000 1.0000
81.6200 149.0000 1.0000
81.6800 144.0000 1.0000
81.7400 143.0000 1.0000
81.8000 146.0000 1.0000
81.8600 135.0000 1.0000
81.9200 122.0000 1.0000
81.9800 149.0000 1.0000
82.0400 126.0000 1.0000
82.1000 136.0000 1.0000
82.1600 144.0000 1.0000
82.2200 150.0000 1.0000
82.2800 161.0000 1.0000
82.3400 128.0000 1.0000
82.4000 158.0000 1.0000
82.4600 153.0000 1.0000
82.5200 123.0000 1.0000
82.5800 142.0000 1.0000
82.6400 126.0000 1.0000
82.7000 129.0000 1.0000
82.7600 160.0000 1.0000
82.8200 123.0000 1.0000
82.8800 149.0000 1.0000
82.9400 145.0000 1.0000
83.0000 146.0000 1.0000
83.0600 146.0000 1.0000
83.1200 133.0000 1.0000
83.1800 177.0000 1.0000
83.2400 155.0000 1.0000
83.3000 174.0000 1.0000
83.3600 178.0000 1.0000
83.4200 205.0000 1.0000
83.4800 181.0000 1.0000
83.5400 227.0000 1.0000
83.6000 281.0000 1.0000
83.6600 526.0000 1.0000
83.7200 1024.0000 1.0000
83.7800 999.0000 1.0000
83.8400 1452.0000 1.0000
83.9000 3762.0000 1.0000
83.9600 1763.0000 1.0000
84.0200 1111.0000 1.0000
84.0800 1179.0000 1.0000
84.1400 1728.0000 1.0000
84.2000 1155.0000 1.0000
84.2600 471.0000 1.0000
84.3200 451.0000 1.0000
84.3800 277.0000 1.0000
84.4400 202.0000 1.0000
84.5000 151.0000 1.0000
84.5600 160.0000 1.0000
84.6200 160.0000 1.0000
84.6800 157.0000 1.0000
84.7400 150.0000 1.0000
84.8000 139.0000 1.0000
84.8600 163.0000 1.0000
84.9200 136.0000 1.0000
84.9800 135.0000 1.0000
85.0400 151.0000 1.0000
85.1000 143.0000 1.0000
85.1600 141.0000 1.0000
85.2200 134.0000 1.0000
85.2800 148.0000 1.0000
85.3400 141.0000 1.0000
85.4000 134.0000 1.0000
85.4600 134.0000 1.0000
85.5200 119.0000 1.0000
85.5800 145.0000 1.0000
85.6400 120.0000 1.0000
85.7000 119.0000 1.0000
85.7600 142.0000 1.0000
85.8200 143.0000 1.0000
85.8800 123.0000 1.0000
85.9400 126.0000 1.0000
86.0000 146.0000 1.0000
86.0600 128.0000 1.0000
86.1200 123.0000 1.0000
86.1800 122.0000 1.0000
86.2400 112.0000 1.0000
86.3000 130.0000 1.0000
86.3600 122.0000 1.0000
86.4200 127.0000 1.0000
86.4800 106.0000 1.0000
86.5400 120.0000 1.0000
86.6000 126.0000 1.0000
86.6600 132.0000 1.0000
86.7200 140.0000 1.0000
86.7800 120.0000 1.0000
86.8400 129.0000 1.0000
86.9000 115.0000 1.0000
86.9600 132.0000 1.0000
87.0200 128.0000 1.0000
87.0800 127.0000 1.0000
87.1400 120.0000 1.0000
87.2000 129.0000 1.0000
87.2600 138.0000 1.0000
87.3200 117.0000 1.0000
87.3800 107.0000 1.0000
87.4400 112.0000 1.0000
87.5000 132.0000 1.0000
87.5600 121.0000 1.0000
87.6200 128.0000 1.0000
87.6800 104.0000 1.0000
87.7400 135.0000 1.0000
87.8000 130.0000 1.0000
87.8600 118.0000 1.0000
87.9200 121.0000 1.0000
87.9800 124.0000 1.0000
88.0400 132.0000 1.0000
88.1000 113.0000 1.0000
88.1600 116.0000 1.0000
88.2200 130.0000 1.0000
88.2800 140.0000 1.0000
88.3400 129.0000 1.0000
88.4000 134.0000 1.0000
88.4600 126.0000 1.0000
88.5200 117.0000 1.0000
88.5800 112.0000 1.0000
88.6400 137.0000 1.0000
88.7000 106.0000 1.0000
88.7600 124.0000 1.0000
88.8200 117.0000 1.0000
88.8800 115.0000 1.0000
88.9400 123.0000 1.0000
89.0000 128.0000 1.0000
89.0600 111.0000 1.0000
89.1200 103.0000 1.0000
89.1800 139.0000 1.0000
89.2400 119.0000 1.0000
89.3000 106.0000 1.0000
89.3600 137.0000 1.0000
89.4200 135.0000 1.0000
89.4800 117.0000 1.0000
89.5400 134.0000 1.0000
89.6000 122.0000 1.0000
89.6600 123.0000 1.0000
89.7200 112.0000 1.0000
89.7800 131.0000 1.0000
89.8400 128.0000 1.0000
89.9000 107.0000 1.0000
89.9600 129.0000 1.0000
90.0200 118.0000 1.0000
90.0800 145.0000 1.0000
90.1400 166.0000 1.0000
90.2000 207.0000 1.0000
90.2600 279.0000 1.0000
90.3200 447.0000 1.0000
90.3800 255.0000 1.0000
90.4400 213.0000 1.0000
90.5000 167.0000 1.0000
90.5600 245.0000 1.0000
90.6200 282.0000 1.0000
90.6800 169.0000 1.0000
90.7400 144.0000 1.0000
90.8000 146.0000 1.0000
90.8600 108.0000 1.0000
90.9200 116.0000 1.0000
90.9800 115.0000 1.0000
91.0400 115.0000 1.0000
91.1000 132.0000 1.0000
91.1600 117.0000 1.0000
91.2200 108.0000 1.0000
91.2800 110.0000 1.0000
91.3400 129.0000 1.0000
91.4000 114.0000 1.0000
91.4600 127.0000 1.0000
91.5200 107.0000 1.0000
91.5800 116.0000 1.0000
91.6400 130.0000 1.0000
91.7000 122.0000 1.0000
91.7600 115.0000 1.0000
91.8200 138.0000 1.0000
91.8800 123.0000 1.0000
91.9400 117.0000 1.0000
92.0000 113.0000 1.0000
92.0600 119.0000 1.0000
92.1200 116.0000 1.0000
92.1800 102.0000 1.0000
92.2400 118.0000 1.0000
92.3000 115.0000 1.0000
92.3600 117.0000 1.0000
92.4200 108.0000 1.0000
92.4800 110.0000 1.0000
92.5400 122.0000 1.0000
92.6000 127.0000 1.0000
92.6600 106.0000 1.0000
92.7200 108.0000 1.0000
92.7800 118.0000 1.0000
92.8400 132.0000 1.0000
92.9000 110.0000 1.0000
92.9600 110.0000 1.0000
93.0200 122.0000 1.0000
93.0800 124.0000 1.0000
93.1400 117.0000 1.0000
93.2000 104.0000 1.0000
93.2600 115.0000 1.0000
93.3200 108.0000 1.0000
93.3800 122.0000 1.0000
93.4400 99.0000 1.0000
93.5000 119.0000 1.0000
93.5600 117.0000 1.0000
93.6200 116.0000 1.0000
93.6800 115.0000 1.0000
93.7400 125.0000 1.0000
93.8000 135.0000 1.0000
93.8600 126.0000 1.0000
93.9200 113.0000 1.0000
93.9800 112.0000 1.0000
94.0400 123.0000 1.0000
94.1000 108.0000 1.0000
94.1600 123.0000 1.0000
94.2200 107.0000 1.0000
94.2800 119.0000 1.0000
94.3400 122.0000 1.0000
94.4000 117.0000 1.0000
94.4600 123.0000 1.0000
94.5200 122.0000 1.0000
94.5800 113.0000 1.0000
94.6400 127.0000 1.0000
94.7000 125.0000 1.0000
94.7600 114.0000 1.0000
94.8200 118.0000 1.0000
94.8800 144.0000 1.0000
94.9400 110.0000 1.0000
95.0000 128.0000 1.0000
95.0600 111.0000 1.0000
95.1200 125.0000 1.0000
95.1800 120.0000 1.0000
95.2400 128.0000 1.0000
95.3000 144.0000 1.0000
95.3600 131.0000 1.0000
95.4200 143.0000 1.0000
95.4800 130.0000 1.0000
95.5400 133.0000 1.0000
95.6000 120.0000 1.0000
95.6600 100.0000 1.0000
95.7200 129.0000 1.0000
95.7800 127.0000 1.0000
95.8400 120.0000 1.0000
95.9000 114.0000 1.0000
95.9600 113.0000 1.0000
96.0200 114.0000 1.0000
96.0800 118.0000 1.0000
96.1400 123.0000 1.0000
96.2000 99.0000 1.0000
96.2600 127.0000 1.0000
96.3200 123.0000 1.0000
96.3800 113.0000 1.0000
96.4400 117.0000 1.0000
96.5000 107.0000 1.0000
96.5600 130.0000 1.0000
96.6200 137.0000 1.0000
96.6800 136.0000 1.0000
96.7400 136.0000 1.0000
96.8000 116.0000 1.0000
96.8600 115.0000 1.0000
96.9200 108.0000 1.0000
96.9800 100.0000 1.0000
97.0400 112.0000 1.0000
97.1000 129.0000 1.0000
97.1600 113.0000 1.0000
97.2200 116.0000 1.0000
97.2800 120.0000 1.0000
97.3400 117.0000 1.0000
97.4000 141.0000 1.0000
97.4600 121.0000 1.0000
97.5200 149.0000 1.0000
97.5800 132.0000 1.0000
97.6400 125.0000 1.0000
97.7000 142.0000 1.0000
97.7600 110.0000 1.0000
97.8200 130.0000 1.0000
97.8800 141.0000 1.0000
97.9400 132.0000 1.0000
98.0000 123.0000 1.0000
98.0600 114.0000 1.0000
98.1200 128.0000 1.0000
98.1800 122.0000 1.0000
98.2400 137.0000 1.0000
98.3000 121.0000 1.0000
98.3600 116.0000 1.0000
98.4200 109.0000 1.0000
98.4800 121.0000 1.0000
98.5400 132.0000 1.0000
98.6000 115.0000 1.0000
98.6600 149.0000 1.0000
98.7200 119.0000 1.0000
98.7800 128.0000 1.0000
98.8400 112.0000 1.0000
98.9000 129.0000 1.0000
98.9600 132.0000 1.0000
99.0200 144.0000 1.0000
99.0800 142.0000 1.0000
99.1400 117.0000 1.0000
99.2000 120.0000 1.0000
99.2600 124.0000 1.0000
99.3200 140.0000 1.0000
99.3800 117.0000 1.0000
99.4400 114.0000 1.0000
99.5000 115.0000 1.0000
99.5600 128.0000 1.0000
99.6200 133.0000 1.0000
99.6800 128.0000 1.0000
99.7400 120.0000 1.0000
99.8000 145.0000 1.0000
99.8600 132.0000 1.0000
99.9200 111.0000 1.0000
99.9800 124.0000 1.0000
100.0000 123.0000 1.0000
*RAS_INT_END
*RAS_DATA_END